2024-03-19 09:41:16,907 - distributed.nanny - INFO -         Start Nanny at: 'tcp://192.41.105.118:45073'
2024-03-19 09:41:18,850 - distributed.worker - INFO -       Start worker at: tcp://192.41.105.118:45237
2024-03-19 09:41:18,851 - distributed.worker - INFO -          Listening to: tcp://192.41.105.118:45237
2024-03-19 09:41:18,851 - distributed.worker - INFO -           Worker name:             SGECluster-168
2024-03-19 09:41:18,852 - distributed.worker - INFO -          dashboard at:       192.41.105.118:39302
2024-03-19 09:41:18,852 - distributed.worker - INFO - Waiting to connect to:  tcp://192.41.105.80:46517
2024-03-19 09:41:18,852 - distributed.worker - INFO - -------------------------------------------------
2024-03-19 09:41:18,852 - distributed.worker - INFO -               Threads:                          1
2024-03-19 09:41:18,852 - distributed.worker - INFO -                Memory:                   7.45 GiB
2024-03-19 09:41:18,852 - distributed.worker - INFO -       Local Directory: /local/41764731.1.igmm_long/dask-scratch-space/worker-dzj1skf1
2024-03-19 09:41:18,852 - distributed.worker - INFO - -------------------------------------------------
2024-03-19 09:41:24,182 - distributed.worker - INFO - Starting Worker plugin shuffle
2024-03-19 09:41:24,183 - distributed.worker - INFO -         Registered to:  tcp://192.41.105.80:46517
2024-03-19 09:41:24,184 - distributed.worker - INFO - -------------------------------------------------
2024-03-19 09:41:24,185 - distributed.core - INFO - Starting established connection to tcp://192.41.105.80:46517
/home/s2211259/khamseh-lab/scematk/env/lib/python3.12/site-packages/dask/core.py:127: RuntimeWarning: divide by zero encountered in log10
  return func(*(_execute_task(a, cache) for a in args))
2024-03-19 09:43:35,058 - distributed.worker - ERROR - Worker stream died during communication: tcp://192.41.105.133:33449
Traceback (most recent call last):
  File "/home/s2211259/khamseh-lab/scematk/env/lib/python3.12/site-packages/distributed/utils.py", line 1935, in wait_for
    return await fut
           ^^^^^^^^^
  File "/home/s2211259/khamseh-lab/scematk/env/lib/python3.12/site-packages/distributed/comm/tcp.py", line 546, in connect
    stream = await self.client.connect(
             ^^^^^^^^^^^^^^^^^^^^^^^^^^
  File "/home/s2211259/khamseh-lab/scematk/env/lib/python3.12/site-packages/tornado/tcpclient.py", line 279, in connect
    af, addr, stream = await connector.start(connect_timeout=timeout)
                       ^^^^^^^^^^^^^^^^^^^^^^^^^^^^^^^^^^^^^^^^^^^^^^
asyncio.exceptions.CancelledError

The above exception was the direct cause of the following exception:

Traceback (most recent call last):
  File "/home/s2211259/khamseh-lab/scematk/env/lib/python3.12/site-packages/distributed/comm/core.py", line 342, in connect
    comm = await wait_for(
           ^^^^^^^^^^^^^^^
  File "/home/s2211259/khamseh-lab/scematk/env/lib/python3.12/site-packages/distributed/utils.py", line 1934, in wait_for
    async with asyncio.timeout(timeout):
  File "/home/s2211259/khamseh-lab/scematk/env/lib/python3.12/asyncio/timeouts.py", line 115, in __aexit__
    raise TimeoutError from exc_val
TimeoutError

The above exception was the direct cause of the following exception:

Traceback (most recent call last):
  File "/home/s2211259/khamseh-lab/scematk/env/lib/python3.12/site-packages/distributed/worker.py", line 2059, in gather_dep
    response = await get_data_from_worker(
               ^^^^^^^^^^^^^^^^^^^^^^^^^^^
  File "/home/s2211259/khamseh-lab/scematk/env/lib/python3.12/site-packages/distributed/worker.py", line 2860, in get_data_from_worker
    comm = await rpc.connect(worker)
           ^^^^^^^^^^^^^^^^^^^^^^^^^
  File "/home/s2211259/khamseh-lab/scematk/env/lib/python3.12/site-packages/distributed/core.py", line 1620, in connect
    return await self._connect(addr=addr, timeout=timeout)
           ^^^^^^^^^^^^^^^^^^^^^^^^^^^^^^^^^^^^^^^^^^^^^^^
  File "/home/s2211259/khamseh-lab/scematk/env/lib/python3.12/site-packages/distributed/core.py", line 1564, in _connect
    comm = await connect(
           ^^^^^^^^^^^^^^
  File "/home/s2211259/khamseh-lab/scematk/env/lib/python3.12/site-packages/distributed/comm/core.py", line 368, in connect
    raise OSError(
OSError: Timed out trying to connect to tcp://192.41.105.133:33449 after 30 s
