2024-03-19 09:26:29,245 - distributed.nanny - INFO -         Start Nanny at: 'tcp://192.41.104.224:38347'
2024-03-19 09:26:30,304 - distributed.worker - INFO -       Start worker at: tcp://192.41.104.224:39360
2024-03-19 09:26:30,304 - distributed.worker - INFO -          Listening to: tcp://192.41.104.224:39360
2024-03-19 09:26:30,304 - distributed.worker - INFO -           Worker name:              SGECluster-82
2024-03-19 09:26:30,306 - distributed.worker - INFO -          dashboard at:       192.41.104.224:34353
2024-03-19 09:26:30,306 - distributed.worker - INFO - Waiting to connect to:  tcp://192.41.105.80:46517
2024-03-19 09:26:30,306 - distributed.worker - INFO - -------------------------------------------------
2024-03-19 09:26:30,306 - distributed.worker - INFO -               Threads:                          1
2024-03-19 09:26:30,306 - distributed.worker - INFO -                Memory:                   7.45 GiB
2024-03-19 09:26:30,306 - distributed.worker - INFO -       Local Directory: /local/41764559.1.eddie/dask-scratch-space/worker-iq3f079u
2024-03-19 09:26:30,306 - distributed.worker - INFO - -------------------------------------------------
2024-03-19 09:26:30,715 - distributed.worker - INFO - Starting Worker plugin shuffle
2024-03-19 09:26:30,716 - distributed.worker - INFO -         Registered to:  tcp://192.41.105.80:46517
2024-03-19 09:26:30,716 - distributed.worker - INFO - -------------------------------------------------
2024-03-19 09:26:30,717 - distributed.core - INFO - Starting established connection to tcp://192.41.105.80:46517
2024-03-19 09:35:22,487 - distributed.core - INFO - Event loop was unresponsive in Worker for 3.33s.  This is often caused by long-running GIL-holding functions or moving large chunks of data. This can cause timeouts and instability.
/home/s2211259/khamseh-lab/scematk/env/lib/python3.12/site-packages/dask/core.py:127: RuntimeWarning: divide by zero encountered in log10
  return func(*(_execute_task(a, cache) for a in args))
2024-03-19 09:43:34,051 - distributed.worker - ERROR - Worker stream died during communication: tcp://192.41.105.88:39723
ConnectionRefusedError: [Errno 111] Connection refused

The above exception was the direct cause of the following exception:

Traceback (most recent call last):
  File "/home/s2211259/khamseh-lab/scematk/env/lib/python3.12/site-packages/distributed/comm/core.py", line 342, in connect
    comm = await wait_for(
           ^^^^^^^^^^^^^^^
  File "/home/s2211259/khamseh-lab/scematk/env/lib/python3.12/site-packages/distributed/utils.py", line 1935, in wait_for
    return await fut
           ^^^^^^^^^
  File "/home/s2211259/khamseh-lab/scematk/env/lib/python3.12/site-packages/distributed/comm/tcp.py", line 559, in connect
    convert_stream_closed_error(self, e)
  File "/home/s2211259/khamseh-lab/scematk/env/lib/python3.12/site-packages/distributed/comm/tcp.py", line 140, in convert_stream_closed_error
    raise CommClosedError(f"in {obj}: {exc.__class__.__name__}: {exc}") from exc
distributed.comm.core.CommClosedError: in <distributed.comm.tcp.TCPConnector object at 0x2ab0f84b6810>: ConnectionRefusedError: [Errno 111] Connection refused

The above exception was the direct cause of the following exception:

Traceback (most recent call last):
  File "/home/s2211259/khamseh-lab/scematk/env/lib/python3.12/site-packages/distributed/worker.py", line 2059, in gather_dep
    response = await get_data_from_worker(
               ^^^^^^^^^^^^^^^^^^^^^^^^^^^
  File "/home/s2211259/khamseh-lab/scematk/env/lib/python3.12/site-packages/distributed/worker.py", line 2860, in get_data_from_worker
    comm = await rpc.connect(worker)
           ^^^^^^^^^^^^^^^^^^^^^^^^^
  File "/home/s2211259/khamseh-lab/scematk/env/lib/python3.12/site-packages/distributed/core.py", line 1620, in connect
    return await self._connect(addr=addr, timeout=timeout)
           ^^^^^^^^^^^^^^^^^^^^^^^^^^^^^^^^^^^^^^^^^^^^^^^
  File "/home/s2211259/khamseh-lab/scematk/env/lib/python3.12/site-packages/distributed/core.py", line 1564, in _connect
    comm = await connect(
           ^^^^^^^^^^^^^^
  File "/home/s2211259/khamseh-lab/scematk/env/lib/python3.12/site-packages/distributed/comm/core.py", line 368, in connect
    raise OSError(
OSError: Timed out trying to connect to tcp://192.41.105.88:39723 after 30 s
2024-03-19 09:48:10,961 - distributed.worker - INFO - Closing worker gracefully: tcp://192.41.104.224:39360. Reason: worker-lifetime-reached
2024-03-19 09:48:11,004 - distributed.worker - INFO - Stopping worker at tcp://192.41.104.224:39360. Reason: worker-lifetime-reached
2024-03-19 09:48:11,011 - distributed.nanny - INFO - Closing Nanny gracefully at 'tcp://192.41.104.224:38347'. Reason: worker-lifetime-reached
2024-03-19 09:48:11,019 - distributed.core - INFO - Connection to tcp://192.41.105.80:46517 has been closed.
2024-03-19 09:48:11,021 - distributed.nanny - INFO - Worker closed
2024-03-19 09:48:15,663 - distributed.nanny - INFO - Closing Nanny at 'tcp://192.41.104.224:38347'. Reason: nanny-close-gracefully
2024-03-19 09:48:15,664 - distributed.dask_worker - INFO - End worker
