2024-03-19 09:22:11,394 - distributed.nanny - INFO -         Start Nanny at: 'tcp://192.41.105.60:39776'
2024-03-19 09:22:12,764 - distributed.worker - INFO -       Start worker at:  tcp://192.41.105.60:38658
2024-03-19 09:22:12,764 - distributed.worker - INFO -          Listening to:  tcp://192.41.105.60:38658
2024-03-19 09:22:12,764 - distributed.worker - INFO -           Worker name:             SGECluster-282
2024-03-19 09:22:12,765 - distributed.worker - INFO -          dashboard at:        192.41.105.60:42220
2024-03-19 09:22:12,765 - distributed.worker - INFO - Waiting to connect to:  tcp://192.41.105.80:46517
2024-03-19 09:22:12,765 - distributed.worker - INFO - -------------------------------------------------
2024-03-19 09:22:12,765 - distributed.worker - INFO -               Threads:                          1
2024-03-19 09:22:12,765 - distributed.worker - INFO -                Memory:                   7.45 GiB
2024-03-19 09:22:12,765 - distributed.worker - INFO -       Local Directory: /local/41764523.1.eddie/dask-scratch-space/worker-0su_ng3t
2024-03-19 09:22:12,765 - distributed.worker - INFO - -------------------------------------------------
2024-03-19 09:22:13,272 - distributed.worker - INFO - Starting Worker plugin shuffle
2024-03-19 09:22:13,273 - distributed.worker - INFO -         Registered to:  tcp://192.41.105.80:46517
2024-03-19 09:22:13,273 - distributed.worker - INFO - -------------------------------------------------
2024-03-19 09:22:13,274 - distributed.core - INFO - Starting established connection to tcp://192.41.105.80:46517
2024-03-19 09:35:23,572 - distributed.core - INFO - Event loop was unresponsive in Worker for 4.40s.  This is often caused by long-running GIL-holding functions or moving large chunks of data. This can cause timeouts and instability.
/home/s2211259/khamseh-lab/scematk/env/lib/python3.12/site-packages/dask/core.py:127: RuntimeWarning: divide by zero encountered in log10
  return func(*(_execute_task(a, cache) for a in args))
2024-03-19 09:42:52,902 - distributed.worker - ERROR - Worker stream died during communication: tcp://192.41.105.90:45252
ConnectionRefusedError: [Errno 111] Connection refused

The above exception was the direct cause of the following exception:

Traceback (most recent call last):
  File "/home/s2211259/khamseh-lab/scematk/env/lib/python3.12/site-packages/distributed/comm/core.py", line 342, in connect
    comm = await wait_for(
           ^^^^^^^^^^^^^^^
  File "/home/s2211259/khamseh-lab/scematk/env/lib/python3.12/site-packages/distributed/utils.py", line 1935, in wait_for
    return await fut
           ^^^^^^^^^
  File "/home/s2211259/khamseh-lab/scematk/env/lib/python3.12/site-packages/distributed/comm/tcp.py", line 559, in connect
    convert_stream_closed_error(self, e)
  File "/home/s2211259/khamseh-lab/scematk/env/lib/python3.12/site-packages/distributed/comm/tcp.py", line 140, in convert_stream_closed_error
    raise CommClosedError(f"in {obj}: {exc.__class__.__name__}: {exc}") from exc
distributed.comm.core.CommClosedError: in <distributed.comm.tcp.TCPConnector object at 0x2ab51b7c4e30>: ConnectionRefusedError: [Errno 111] Connection refused

The above exception was the direct cause of the following exception:

Traceback (most recent call last):
  File "/home/s2211259/khamseh-lab/scematk/env/lib/python3.12/site-packages/distributed/worker.py", line 2059, in gather_dep
    response = await get_data_from_worker(
               ^^^^^^^^^^^^^^^^^^^^^^^^^^^
  File "/home/s2211259/khamseh-lab/scematk/env/lib/python3.12/site-packages/distributed/worker.py", line 2860, in get_data_from_worker
    comm = await rpc.connect(worker)
           ^^^^^^^^^^^^^^^^^^^^^^^^^
  File "/home/s2211259/khamseh-lab/scematk/env/lib/python3.12/site-packages/distributed/core.py", line 1620, in connect
    return await self._connect(addr=addr, timeout=timeout)
           ^^^^^^^^^^^^^^^^^^^^^^^^^^^^^^^^^^^^^^^^^^^^^^^
  File "/home/s2211259/khamseh-lab/scematk/env/lib/python3.12/site-packages/distributed/core.py", line 1564, in _connect
    comm = await connect(
           ^^^^^^^^^^^^^^
  File "/home/s2211259/khamseh-lab/scematk/env/lib/python3.12/site-packages/distributed/comm/core.py", line 368, in connect
    raise OSError(
OSError: Timed out trying to connect to tcp://192.41.105.90:45252 after 30 s
2024-03-19 09:43:37,296 - distributed.worker - INFO - Closing worker gracefully: tcp://192.41.105.60:38658. Reason: worker-lifetime-reached
2024-03-19 09:43:37,337 - distributed.worker - INFO - Stopping worker at tcp://192.41.105.60:38658. Reason: worker-lifetime-reached
2024-03-19 09:43:37,343 - distributed.nanny - INFO - Closing Nanny gracefully at 'tcp://192.41.105.60:39776'. Reason: worker-lifetime-reached
2024-03-19 09:43:37,353 - distributed.core - INFO - Connection to tcp://192.41.105.80:46517 has been closed.
2024-03-19 09:43:37,354 - distributed.nanny - INFO - Worker closed
2024-03-19 09:43:39,768 - distributed.nanny - INFO - Closing Nanny at 'tcp://192.41.105.60:39776'. Reason: nanny-close-gracefully
2024-03-19 09:43:39,769 - distributed.dask_worker - INFO - End worker
