2024-03-19 09:18:02,232 - distributed.nanny - INFO -         Start Nanny at: 'tcp://192.41.105.146:44913'
2024-03-19 09:18:03,446 - distributed.worker - INFO -       Start worker at: tcp://192.41.105.146:43576
2024-03-19 09:18:03,446 - distributed.worker - INFO -          Listening to: tcp://192.41.105.146:43576
2024-03-19 09:18:03,446 - distributed.worker - INFO -           Worker name:              SGECluster-74
2024-03-19 09:18:03,448 - distributed.worker - INFO -          dashboard at:       192.41.105.146:35279
2024-03-19 09:18:03,448 - distributed.worker - INFO - Waiting to connect to:  tcp://192.41.105.80:46517
2024-03-19 09:18:03,449 - distributed.worker - INFO - -------------------------------------------------
2024-03-19 09:18:03,449 - distributed.worker - INFO -               Threads:                          1
2024-03-19 09:18:03,449 - distributed.worker - INFO -                Memory:                   7.45 GiB
2024-03-19 09:18:03,449 - distributed.worker - INFO -       Local Directory: /local/41764436.1.igmm_long/dask-scratch-space/worker-4mmz8fkp
2024-03-19 09:18:03,449 - distributed.worker - INFO - -------------------------------------------------
2024-03-19 09:18:04,214 - distributed.worker - INFO - Starting Worker plugin shuffle
2024-03-19 09:18:04,214 - distributed.worker - INFO -         Registered to:  tcp://192.41.105.80:46517
2024-03-19 09:18:04,214 - distributed.worker - INFO - -------------------------------------------------
2024-03-19 09:18:04,215 - distributed.core - INFO - Starting established connection to tcp://192.41.105.80:46517
/home/s2211259/khamseh-lab/scematk/env/lib/python3.12/site-packages/dask/core.py:127: RuntimeWarning: divide by zero encountered in log10
  return func(*(_execute_task(a, cache) for a in args))
2024-03-19 09:43:04,383 - distributed.worker - ERROR - Worker stream died during communication: tcp://192.41.105.88:39723
ConnectionRefusedError: [Errno 111] Connection refused

The above exception was the direct cause of the following exception:

Traceback (most recent call last):
  File "/home/s2211259/khamseh-lab/scematk/env/lib/python3.12/site-packages/distributed/comm/core.py", line 342, in connect
    comm = await wait_for(
           ^^^^^^^^^^^^^^^
  File "/home/s2211259/khamseh-lab/scematk/env/lib/python3.12/site-packages/distributed/utils.py", line 1935, in wait_for
    return await fut
           ^^^^^^^^^
  File "/home/s2211259/khamseh-lab/scematk/env/lib/python3.12/site-packages/distributed/comm/tcp.py", line 559, in connect
    convert_stream_closed_error(self, e)
  File "/home/s2211259/khamseh-lab/scematk/env/lib/python3.12/site-packages/distributed/comm/tcp.py", line 140, in convert_stream_closed_error
    raise CommClosedError(f"in {obj}: {exc.__class__.__name__}: {exc}") from exc
distributed.comm.core.CommClosedError: in <distributed.comm.tcp.TCPConnector object at 0x2b9ec298b4a0>: ConnectionRefusedError: [Errno 111] Connection refused

During handling of the above exception, another exception occurred:

Traceback (most recent call last):
  File "/home/s2211259/khamseh-lab/scematk/env/lib/python3.12/site-packages/distributed/core.py", line 1620, in connect
    return await self._connect(addr=addr, timeout=timeout)
           ^^^^^^^^^^^^^^^^^^^^^^^^^^^^^^^^^^^^^^^^^^^^^^^
  File "/home/s2211259/khamseh-lab/scematk/env/lib/python3.12/site-packages/distributed/core.py", line 1564, in _connect
    comm = await connect(
           ^^^^^^^^^^^^^^
  File "/home/s2211259/khamseh-lab/scematk/env/lib/python3.12/site-packages/distributed/comm/core.py", line 366, in connect
    await asyncio.sleep(backoff)
  File "/home/s2211259/khamseh-lab/scematk/env/lib/python3.12/asyncio/tasks.py", line 665, in sleep
    return await future
           ^^^^^^^^^^^^
asyncio.exceptions.CancelledError

The above exception was the direct cause of the following exception:

Traceback (most recent call last):
  File "/home/s2211259/khamseh-lab/scematk/env/lib/python3.12/site-packages/distributed/core.py", line 1611, in connect
    async with asyncio.timeout(math.inf) as scope:
  File "/home/s2211259/khamseh-lab/scematk/env/lib/python3.12/asyncio/timeouts.py", line 115, in __aexit__
    raise TimeoutError from exc_val
TimeoutError

During handling of the above exception, another exception occurred:

Traceback (most recent call last):
  File "/home/s2211259/khamseh-lab/scematk/env/lib/python3.12/site-packages/distributed/worker.py", line 2059, in gather_dep
    response = await get_data_from_worker(
               ^^^^^^^^^^^^^^^^^^^^^^^^^^^
  File "/home/s2211259/khamseh-lab/scematk/env/lib/python3.12/site-packages/distributed/worker.py", line 2860, in get_data_from_worker
    comm = await rpc.connect(worker)
           ^^^^^^^^^^^^^^^^^^^^^^^^^
  File "/home/s2211259/khamseh-lab/scematk/env/lib/python3.12/site-packages/distributed/core.py", line 1632, in connect
    raise CommClosedError(reason)
distributed.comm.core.CommClosedError: Address removed.
2024-03-19 09:43:41,362 - distributed.worker - INFO - Closing worker gracefully: tcp://192.41.105.146:43576. Reason: worker-lifetime-reached
2024-03-19 09:43:41,406 - distributed.worker - INFO - Stopping worker at tcp://192.41.105.146:43576. Reason: worker-lifetime-reached
2024-03-19 09:43:41,409 - distributed.nanny - INFO - Closing Nanny gracefully at 'tcp://192.41.105.146:44913'. Reason: worker-lifetime-reached
2024-03-19 09:43:41,418 - distributed.core - INFO - Connection to tcp://192.41.105.80:46517 has been closed.
2024-03-19 09:43:41,419 - distributed.nanny - INFO - Worker closed
2024-03-19 09:43:44,607 - distributed.nanny - INFO - Closing Nanny at 'tcp://192.41.105.146:44913'. Reason: nanny-close-gracefully
2024-03-19 09:43:44,608 - distributed.dask_worker - INFO - End worker
