2024-03-19 09:41:14,934 - distributed.nanny - INFO -         Start Nanny at: 'tcp://192.41.105.85:37221'
2024-03-19 09:41:16,691 - distributed.worker - INFO -       Start worker at:  tcp://192.41.105.85:35756
2024-03-19 09:41:16,691 - distributed.worker - INFO -          Listening to:  tcp://192.41.105.85:35756
2024-03-19 09:41:16,691 - distributed.worker - INFO -           Worker name:              SGECluster-24
2024-03-19 09:41:16,692 - distributed.worker - INFO -          dashboard at:        192.41.105.85:40202
2024-03-19 09:41:16,692 - distributed.worker - INFO - Waiting to connect to:  tcp://192.41.105.80:46517
2024-03-19 09:41:16,693 - distributed.worker - INFO - -------------------------------------------------
2024-03-19 09:41:16,693 - distributed.worker - INFO -               Threads:                          1
2024-03-19 09:41:16,693 - distributed.worker - INFO -                Memory:                   7.45 GiB
2024-03-19 09:41:16,693 - distributed.worker - INFO -       Local Directory: /local/41764748.1.igmm_long/dask-scratch-space/worker-n2zd0d6z
2024-03-19 09:41:16,693 - distributed.worker - INFO - -------------------------------------------------
2024-03-19 09:41:18,455 - distributed.worker - INFO - Starting Worker plugin shuffle
2024-03-19 09:41:18,456 - distributed.worker - INFO -         Registered to:  tcp://192.41.105.80:46517
2024-03-19 09:41:18,456 - distributed.worker - INFO - -------------------------------------------------
2024-03-19 09:41:18,457 - distributed.core - INFO - Starting established connection to tcp://192.41.105.80:46517
/home/s2211259/khamseh-lab/scematk/env/lib/python3.12/site-packages/dask/core.py:127: RuntimeWarning: divide by zero encountered in log10
  return func(*(_execute_task(a, cache) for a in args))
2024-03-19 09:42:53,038 - distributed.worker - ERROR - Worker stream died during communication: tcp://192.41.105.90:45252
ConnectionRefusedError: [Errno 111] Connection refused

The above exception was the direct cause of the following exception:

Traceback (most recent call last):
  File "/home/s2211259/khamseh-lab/scematk/env/lib/python3.12/site-packages/distributed/comm/core.py", line 342, in connect
    comm = await wait_for(
           ^^^^^^^^^^^^^^^
  File "/home/s2211259/khamseh-lab/scematk/env/lib/python3.12/site-packages/distributed/utils.py", line 1935, in wait_for
    return await fut
           ^^^^^^^^^
  File "/home/s2211259/khamseh-lab/scematk/env/lib/python3.12/site-packages/distributed/comm/tcp.py", line 559, in connect
    convert_stream_closed_error(self, e)
  File "/home/s2211259/khamseh-lab/scematk/env/lib/python3.12/site-packages/distributed/comm/tcp.py", line 140, in convert_stream_closed_error
    raise CommClosedError(f"in {obj}: {exc.__class__.__name__}: {exc}") from exc
distributed.comm.core.CommClosedError: in <distributed.comm.tcp.TCPConnector object at 0x2b6e85792b40>: ConnectionRefusedError: [Errno 111] Connection refused

The above exception was the direct cause of the following exception:

Traceback (most recent call last):
  File "/home/s2211259/khamseh-lab/scematk/env/lib/python3.12/site-packages/distributed/worker.py", line 2059, in gather_dep
    response = await get_data_from_worker(
               ^^^^^^^^^^^^^^^^^^^^^^^^^^^
  File "/home/s2211259/khamseh-lab/scematk/env/lib/python3.12/site-packages/distributed/worker.py", line 2860, in get_data_from_worker
    comm = await rpc.connect(worker)
           ^^^^^^^^^^^^^^^^^^^^^^^^^
  File "/home/s2211259/khamseh-lab/scematk/env/lib/python3.12/site-packages/distributed/core.py", line 1620, in connect
    return await self._connect(addr=addr, timeout=timeout)
           ^^^^^^^^^^^^^^^^^^^^^^^^^^^^^^^^^^^^^^^^^^^^^^^
  File "/home/s2211259/khamseh-lab/scematk/env/lib/python3.12/site-packages/distributed/core.py", line 1564, in _connect
    comm = await connect(
           ^^^^^^^^^^^^^^
  File "/home/s2211259/khamseh-lab/scematk/env/lib/python3.12/site-packages/distributed/comm/core.py", line 368, in connect
    raise OSError(
OSError: Timed out trying to connect to tcp://192.41.105.90:45252 after 30 s
